<?xml version="1.0" ?>
<robot name="plane">
    <link name="chassis">
        <contact>
            <lateral_friction value="1"/>
        </contact>
        <inertial>
            <origin rpy="0 0 0" xyz="0.002284 -0.000041 0.025165"/>
            <mass value="13.733"/>
            <inertia ixx="0.073348887" ixy="0.00030338" ixz="0.001918218" iyy="0.250684593" iyz="-0.000075402" izz="0.254469458"/>
        </inertial>
        <visual>
            <origin rpy="0 0 0" xyz="0 0 0"/>
            <geometry>
                <mesh filename="_trunk.stl" scale="1 1 1"/>
            </geometry>
            <material name="white">
                <color rgba="1 1 1 1"/>
            </material>
        </visual>
        <collision>
            <origin rpy="0 0 0" xyz="0 0 0"/>
            <geometry>
                <mesh filename="_trunk.stl" scale="1 1 1"/>
            </geometry>
        </collision>
    </link>
    <link name="FR_hip_motor">
        <contact>
            <lateral_friction value="1"/>
        </contact>
        <inertial>
            <origin rpy="0 0 0" xyz="-0.001568 0.008134 0.000864"/>
            <mass value="1.096"/>
            <inertia ixx="0.000822113" ixy="0.000004982" ixz="-0.00003672" iyy="0.000983196" iyz="-0.000002811" izz="0.000864753"/>
        </inertial>

        <visual>
            <origin rpy="0 0 0" xyz="0 0 0"/>
            <geometry>
                <mesh filename="_hip.stl" scale="1 1 1"/>
            </geometry>
            <material name="white"/>
        </visual>

        <collision>
            <origin rpy="0 0 0" xyz="0 0 0"/>
            <geometry>
                <mesh filename="_hip.stl" scale="1 1 1"/>
            </geometry>
        </collision>
    </link>

    <joint name="FR_hip_motor_2_chassis_joint" type="revolute">
        <axis xyz="1 0 0"/>
        <parent link="chassis"/>
        <child link="FR_hip_motor"/>
        <origin rpy="0 0 0" xyz="0.21935 -0.0875 0"/>
        <limit effort="100" velocity="100" lower="-1.0472" upper="0.872665"/>
        <joint_properties damping=".0" friction=".0"/>
    </joint>

    <link name="FR_upper_leg">
        <contact>
            <lateral_friction value="1"/>
        </contact>
        <inertial>
            <origin rpy="0 0 0" xyz="-0.000482 -0.02001 -0.031996"/>
            <mass value="1.528"/>
            <inertia ixx="0.00991611" ixy="-0.000010388" ixz="0.000250428" iyy="0.009280083" iyz="0.00008511" izz="0.00178256"/>
        </inertial>
        <visual>
            <origin rpy="0 0 0" xyz="0 0 0"/>
            <geometry>
                <mesh filename="_thigh_mirror.stl" scale="1 1 1"/>
            </geometry>
            <material name="white"/>
        </visual>

        <collision>
            <origin rpy="0 0 0" xyz="0 0 0"/>
            <geometry>
                <mesh filename="_thigh_mirror.stl" scale="1 1 1"/>
            </geometry>
        </collision>

    </link>

    <joint name="FR_upper_leg_2_hip_motor_joint" type="revolute">
        <axis xyz="0 1 0"/>
        <parent link="FR_hip_motor"/>
        <child link="FR_upper_leg"/>
        <origin rpy="0 0 0" xyz="0 -0.037 0"/>
        <limit effort="100" velocity="100" lower="-0.523599" upper="3.92699"/>
        <joint_properties damping=".0" friction=".0"/>
    </joint>

    <link name="FR_lower_leg">
        <contact>
            <lateral_friction value="1"/>
        </contact>
        <inertial>
            <origin rpy="0 0 0" xyz="-0.002196 -0.000381 -0.12338"/>
            <mass value="0.241"/>
            <inertia ixx="0.006181961" ixy="0.000000237" ixz="-0.000002985" iyy="0.006196546" iyz="0.000005138" izz="0.000034774"/>
        </inertial>
        <visual>
            <origin rpy="0 0 0" xyz="0 0 0"/>
            <geometry>
                <mesh filename="_calf.stl" scale="1 1 1"/>
            </geometry>
            <material name="white"/>
        </visual>

        <collision>
            <origin rpy="0 0 0" xyz="0 0 0"/>
            <geometry>
                <mesh filename="_calf.stl" scale="1 1 1"/>
            </geometry>
        </collision>
    </link>
    <joint name="FR_lower_leg_2_upper_leg_joint" type="revolute">
        <axis xyz="0 1 0"/>
        <parent link="FR_upper_leg"/>
        <child link="FR_lower_leg"/>

        <origin rpy="0 0 0" xyz="0 0 -0.25"/>
        <limit effort="100" velocity="100" lower="-2.77507" upper="-0.610865"/>
        <joint_properties damping=".0" friction=".0"/>
    </joint>


    <link name="FL_hip_motor">
        <contact>
            <lateral_friction value="1"/>
        </contact>
        <inertial>
            <origin rpy="0 0 0" xyz="-0.001568 -0.008134 0.000864"/>
            <mass value="1.096"/>
            <inertia ixx="0.000822113" ixy="-0.000004982" ixz="-0.00003672" iyy="0.000983196" iyz="0.000002811" izz="0.000864753"/>
        </inertial>
        <visual>
            <origin rpy="3.14 0 0" xyz="0 0 0"/>
            <geometry>
                <mesh filename="_hip.stl" scale="1 1 1"/>
            </geometry>
            <material name="white">
            </material>
        </visual>

        <collision>
            <origin rpy="3.14 0 0" xyz="0 0 0"/>
            <geometry>
                <mesh filename="_hip.stl" scale="1 1 1"/>
            </geometry>
        </collision>

    </link>

    <joint name="FL_hip_motor_2_chassis_joint" type="revolute">
        <axis xyz="1 0 0"/>
        <parent link="chassis"/>
        <child link="FL_hip_motor"/>
        <origin rpy="0 0 0" xyz="0.21935 0.0875 0"/>
        <limit effort="100" velocity="100" lower="-0.872665" upper="1.0472"/>
        <joint_properties damping=".0" friction=".0"/>
    </joint>

    <link name="FL_upper_leg">
        <contact>
            <lateral_friction value="1"/>
        </contact>
        <inertial>
            <origin rpy="0 0 0" xyz="-0.000482 0.02001 -0.031996"/>
            <mass value="1.528"/>
            <inertia ixx="0.00991611" ixy="0.000010388" ixz="0.000250428" iyy="0.009280083" iyz="-0.00008511" izz="0.00178256"/>
        </inertial>
        <visual>
            <origin rpy="0 0 0" xyz="0 0 0"/>
            <geometry>

                <mesh filename="_thigh.stl" scale="1 1 1"/>
            </geometry>
            <material name="white">
            </material>
        </visual>

        <collision>
            <origin rpy="0 0 0" xyz="0 0 0"/>
            <geometry>
                <mesh filename="_thigh.stl" scale="1 1 1"/>
            </geometry>
        </collision>

    </link>


    <joint name="FL_upper_leg_2_hip_motor_joint" type="revolute">
        <axis xyz="0 1 0"/>
        <parent link="FL_hip_motor"/>
        <child link="FL_upper_leg"/>
        <origin rpy="0 0 0" xyz="0 0.037 0"/>
        <limit effort="100" velocity="100" lower="-0.523599" upper="3.92699"/>
        <joint_properties damping=".0" friction=".0"/>
    </joint>


    <link name="FL_lower_leg">
        <contact>
            <lateral_friction value="1"/>
        </contact>
        <inertial>
            <origin rpy="0 0 0" xyz="-0.002196 -0.000381 -0.12338"/>
            <mass value="0.241"/>
            <inertia ixx="0.006181961" ixy="0.000000237" ixz="-0.000002985" iyy="0.006196546" iyz="0.000005138" izz="0.000034774"/>
        </inertial>
        <visual>
            <origin rpy="0 0 0" xyz="0 0 0"/>
            <geometry>
                <mesh filename="_calf.stl" scale="1 1 1"/>
            </geometry>
            <material name="white">
            </material>
        </visual>

        <collision>
            <origin rpy="0 0 0" xyz="0 0 0"/>
            <geometry>
                <mesh filename="_calf.stl" scale="1 1 1"/>
            </geometry>
        </collision>

    </link>

    <joint name="FL_lower_leg_2_upper_leg_joint" type="revolute">
        <axis xyz="0 1 0"/>
        <parent link="FL_upper_leg"/>
        <child link="FL_lower_leg"/>
        <origin rpy="0 0 0" xyz="0 0 -0.25"/>
        <limit effort="100" velocity="100" lower="-2.77507" upper="-0.610865"/>
        <joint_properties damping=".0" friction=".0"/>
    </joint>

    <link name="RR_hip_motor">
        <contact>
            <lateral_friction value="1"/>
        </contact>
        <inertial>
            <origin rpy="0 0 0" xyz="0.001568 0.008134 0.000864"/>
            <mass value="1.096"/>
            <inertia ixx="0.000822113" ixy="-0.000004982" ixz="0.00003672" iyy="0.000983196" iyz="-0.000002811" izz="0.000864753"/>
        </inertial>

        <visual>
            <origin rpy="0 0 0" xyz="0 0 0"/>
            <geometry>
                <mesh filename="_hip.stl" scale="1 1 1"/>
            </geometry>
            <material name="white"/>
        </visual>

        <collision>
            <origin rpy="0 0 0" xyz="0 0 0"/>
            <geometry>
                <mesh filename="_hip.stl" scale="1 1 1"/>
            </geometry>
        </collision>
    </link>

    <joint name="RR_hip_motor_2_chassis_joint" type="revolute">
        <axis xyz="1 0 0"/>
        <parent link="chassis"/>
        <child link="RR_hip_motor"/>
        <origin rpy="0 0 0" xyz="-0.21935 -0.0875 0"/>
        <limit effort="100" velocity="100" lower="-1.0472" upper="0.872665"/>
        <joint_properties damping=".0" friction=".0"/>
    </joint>

    <link name="RR_upper_leg">
        <contact>
            <lateral_friction value="1"/>
        </contact>
        <inertial>
            <origin rpy="0 0 0" xyz="-0.000482 -0.02001 -0.031996"/>
            <mass value="1.528"/>
            <inertia ixx="0.00991611" ixy="-0.000010388" ixz="0.000250428" iyy="0.009280083" iyz="0.00008511" izz="0.00178256"/>
        </inertial>
        <visual>
            <origin rpy="0 0 0" xyz="0 0 0"/>
            <geometry>
                <mesh filename="_thigh_mirror.stl" scale="1 1 1"/>
            </geometry>
            <material name="white"/>
        </visual>

        <collision>
            <origin rpy="0 0 0" xyz="0 0 0"/>
            <geometry>
                <mesh filename="_thigh_mirror.stl" scale="1 1 1"/>
            </geometry>
        </collision>

    </link>

    <joint name="RR_upper_leg_2_hip_motor_joint" type="revolute">
        <axis xyz="0 1 0"/>
        <parent link="RR_hip_motor"/>
        <child link="RR_upper_leg"/>
        <origin rpy="0 0 0" xyz="0 -0.037 0"/>
        <limit effort="100" velocity="100" lower="-0.523599" upper="3.92699"/>
        <joint_properties damping=".0" friction=".0"/>
    </joint>

    <link name="RR_lower_leg">
        <contact>
            <lateral_friction value="1"/>
        </contact>
        <inertial>
            <origin rpy="0 0 0" xyz="-0.002196 -0.000381 -0.12338"/>
            <mass value="0.241"/>
            <inertia ixx="0.006181961" ixy="0.000000237" ixz="-0.000002985" iyy="0.006196546" iyz="0.000005138" izz="0.000034774"/>
        </inertial>
        <visual>
            <origin rpy="0 0 0" xyz="0 0 0"/>
            <geometry>
                <mesh filename="_calf.stl" scale="1 1 1"/>
            </geometry>
            <material name="white"/>
        </visual>

        <collision>
            <origin rpy="0 0 0" xyz="0 0 0"/>
            <geometry>
                <mesh filename="_calf.stl" scale="1 1 1"/>
            </geometry>
        </collision>

    </link>

    <joint name="RR_lower_leg_2_upper_leg_joint" type="revolute">
        <axis xyz="0 1 0"/>
        <parent link="RR_upper_leg"/>
        <child link="RR_lower_leg"/>
        <origin rpy="0 0 0" xyz="0 0 -0.25"/>
        <limit effort="100" velocity="100" lower="-2.77507" upper="-0.610865"/>
        <joint_properties damping=".0" friction=".0"/>
    </joint>


    <link name="RL_hip_motor">
        <contact>
            <lateral_friction value="1"/>
        </contact>
        <inertial>
            <origin rpy="0 0 0" xyz="0.001568 -0.008134 0.000864"/>
            <mass value="1.096"/>
            <inertia ixx="0.000822113" ixy="0.000004982" ixz="0.00003672" iyy="0.000983196" iyz="0.000002811" izz="0.000864753"/>
        </inertial>
        <visual>
            <origin rpy="3.14 0 0" xyz="0 0 0"/>
            <geometry>
                <mesh filename="_hip.stl" scale="1 1 1"/>
            </geometry>
            <material name="white"/>
        </visual>

        <collision>
            <origin rpy="3.14 0 0" xyz="0 0 0"/>
            <geometry>
                <mesh filename="_hip.stl" scale="1 1 1"/>
            </geometry>
        </collision>

    </link>

    <joint name="RL_hip_motor_2_chassis_joint" type="revolute">
        <axis xyz="1 0 0"/>
        <parent link="chassis"/>
        <child link="RL_hip_motor"/>
        <origin rpy="0 0 0" xyz="-0.21935 0.0875 0"/>
        <limit effort="100" velocity="100" lower="-0.872665" upper="1.0472"/>
        <joint_properties damping=".0" friction=".0"/>
    </joint>

    <link name="RL_upper_leg">
        <contact>
            <lateral_friction value="1"/>
        </contact>
        <inertial>
            <origin rpy="0 0 0" xyz="-0.000482 0.02001 -0.031996"/>
            <mass value="1.528"/>
            <inertia ixx="0.00991611" ixy="0.000010388" ixz="0.000250428" iyy="0.009280083" iyz="-0.00008511" izz="0.00178256"/>
        </inertial>
        <visual>
            <origin rpy="0 0 0" xyz="0 0 0"/>
            <geometry>
                <mesh filename="_thigh.stl" scale="1 1 1"/>
            </geometry>
            <material name="white"/>
        </visual>

        <collision>
            <origin rpy="0 0 0" xyz="0 0 0"/>
            <geometry>
                <mesh filename="_thigh.stl" scale="1 1 1"/>
            </geometry>
        </collision>

    </link>


    <joint name="RL_upper_leg_2_hip_motor_joint" type="revolute">
        <axis xyz="0 1 0"/>
        <parent link="RL_hip_motor"/>
        <child link="RL_upper_leg"/>
        <origin rpy="0 0 0" xyz="0 0.037 0"/>
        <limit effort="100" velocity="100" lower="-0.523599" upper="3.92699"/>
        <joint_properties damping=".0" friction=".0"/>
    </joint>


    <link name="RL_lower_leg">
        <contact>
            <lateral_friction value="1"/>
        </contact>
        <inertial>
            <origin rpy="0 0 0" xyz="-0.002196 -0.000381 -0.12338"/>
            <mass value="0.241"/>
            <inertia ixx="0.006181961" ixy="0.000000237" ixz="-0.000002985" iyy="0.006196546" iyz="0.000005138" izz="0.000034774"/>
        </inertial>
        <visual>
            <origin rpy="0 0 0" xyz="0 0 0"/>
            <geometry>
                <mesh filename="_calf.stl" scale="1 1 1"/>
            </geometry>
            <material name="white"/>
        </visual>

        <collision>
            <origin rpy="0 0 0" xyz="0 0 0"/>
            <geometry>
                <mesh filename="_calf.stl" scale="1 1 1"/>
            </geometry>
        </collision>

    </link>

    <joint name="RL_lower_leg_2_upper_leg_joint" type="revolute">
        <axis xyz="0 1 0"/>
        <parent link="RL_upper_leg"/>
        <child link="RL_lower_leg"/>
        <origin rpy="0 0 0" xyz="0 0 -0.25"/>
        <limit effort="100" velocity="100" lower="-2.77507" upper="-0.610865"/>
        <joint_properties damping=".0" friction=".0"/>
    </joint>

    <link name="toeRL">
        <contact>
            <friction_anchor/>
            <stiffness value="30000.0"/>
            <damping value="1000.0"/>
            <spinning_friction value="0.1"/>
            <lateral_friction value="1.0"/>
        </contact>
        <visual>
            <origin rpy="0 0 0" xyz="0 0 0"/>
            <geometry>
                <sphere radius="0.0"/>
            </geometry>
            <material name="white"/>
        </visual>
        <collision>
            <origin rpy="0 0 0" xyz="0 0 0"/>
            <geometry>
                <sphere radius="0.03"/>
            </geometry>
        </collision>
        <inertial>
            <mass value="0.001"/>
            <inertia ixx="0.000005" ixy="0" ixz="0" iyy="0.000005" iyz="0" izz="0.000005"/>
        </inertial>
    </link>
    <joint name="jtoeRL" type="fixed">
        <parent link="RL_lower_leg"/>
        <child link="toeRL"/>
        <origin xyz="-0.005 0 -0.255"/>
        <dynamics damping="0.0" friction="0.0"/>
    </joint>

    <link name="toeRR">
        <contact>
            <friction_anchor/>
            <stiffness value="30000.0"/>
            <damping value="1000.0"/>
            <spinning_friction value="0.1"/>
            <lateral_friction value="1.0"/>
        </contact>
        <visual>
            <origin rpy="0 0 0" xyz="0 0 0"/>
            <geometry>
                <sphere radius="0.0"/>
            </geometry>
            <material name="white"/>
        </visual>
        <collision>
            <origin rpy="0 0 0" xyz="0 0 0"/>
            <geometry>
                <sphere radius="0.03"/>
            </geometry>
        </collision>
        <inertial>
            <mass value="0.001"/>
            <inertia ixx="0.000005" ixy="0" ixz="0" iyy="0.000005" iyz="0" izz="0.000005"/>
        </inertial>
    </link>
    <joint name="jtoeRR" type="fixed">
        <parent link="RR_lower_leg"/>
        <child link="toeRR"/>
        <origin xyz="-0.005 0 -0.255"/>
        <dynamics damping="0.0" friction="0.0"/>
    </joint>

    <link name="toeFL">
        <contact>
            <friction_anchor/>
            <stiffness value="30000.0"/>
            <damping value="1000.0"/>
            <spinning_friction value="0.1"/>
            <lateral_friction value="1.0"/>
        </contact>
        <visual>
            <origin rpy="0 0 0" xyz="0 0 0"/>
            <geometry>
                <sphere radius="0.0"/>
            </geometry>
            <material name="white"/>
        </visual>
        <collision>
            <origin rpy="0 0 0" xyz="0 0 0"/>
            <geometry>
                <sphere radius="0.03"/>
            </geometry>
        </collision>
        <inertial>
            <mass value="0.001"/>
            <inertia ixx="0.000005" ixy="0" ixz="0" iyy="0.000005" iyz="0" izz="0.000005"/>
        </inertial>
    </link>
    <joint name="jtoeFL" type="fixed">
        <parent link="FL_lower_leg"/>
        <child link="toeFL"/>
        <origin xyz="-0.005 0 -0.255"/>
        <dynamics damping="0.0" friction="0.0"/>
    </joint>

    <link name="toeFR">
        <contact>
            <friction_anchor/>
            <stiffness value="30000.0"/>
            <damping value="1000.0"/>
            <spinning_friction value="0.1"/>
            <lateral_friction value="1.0"/>
        </contact>
        <visual>
            <origin rpy="0 0 0" xyz="0 0 0"/>
            <geometry>
                <sphere radius="0.0"/>
            </geometry>
            <material name="white"/>
        </visual>
        <collision>
            <origin rpy="0 0 0" xyz="0 0 0"/>
            <geometry>
                <sphere radius="0.03"/>
            </geometry>
        </collision>
        <inertial>
            <mass value="0.001"/>
            <inertia ixx="0.000005" ixy="0" ixz="0" iyy="0.000005" iyz="0" izz="0.000005"/>
        </inertial>
    </link>
    <joint name="jtoeFR" type="fixed">
        <parent link="FR_lower_leg"/>
        <child link="toeFR"/>
        <origin xyz="-0.005 0 -0.255"/>
        <dynamics damping="0.0" friction="0.0"/>
    </joint>
</robot>
